2021-10-02 12:38:56 ERROR Traceback (most recent call last):
  File "c:\users\heinz\anaconda3\lib\site-packages\wandb\cli\cli.py", line 85, in wrapper
    return func(*args, **kwargs)
  File "c:\users\heinz\anaconda3\lib\site-packages\wandb\cli\cli.py", line 233, in login
    wandb.login(relogin=relogin, key=key, anonymous=anon_mode, host=host, force=True)
  File "c:\users\heinz\anaconda3\lib\site-packages\wandb\sdk\wandb_login.py", line 65, in login
    configured = _login(**kwargs)
  File "c:\users\heinz\anaconda3\lib\site-packages\wandb\sdk\wandb_login.py", line 274, in _login
    wlogin.prompt_api_key()
  File "c:\users\heinz\anaconda3\lib\site-packages\wandb\sdk\wandb_login.py", line 209, in prompt_api_key
    raise UsageError("api_key not configured (no-tty). call " + directive)
wandb.errors.UsageError: api_key not configured (no-tty). call wandb login [your_api_key]

