2021-10-02 12:42:36,258 INFO    MainThread:36220 [internal.py:wandb_internal():86] W&B internal server running at pid: 36220, started at: 2021-10-02 12:42:36.241320
2021-10-02 12:42:36,260 INFO    WriterThread:36220 [datastore.py:open_for_write():77] open: C:\Users\heinz\Documents\GitHub\Google_Brain-Ventilator_Pressure_Prediction\wandb\run-20211002_124233-c21n7t6e\run-c21n7t6e.wandb
2021-10-02 12:42:36,260 DEBUG   HandlerThread:36220 [handler.py:handle_request():126] handle_request: check_version
2021-10-02 12:42:36,270 DEBUG   SenderThread:36220 [sender.py:send():185] send: header
2021-10-02 12:42:36,271 DEBUG   SenderThread:36220 [sender.py:send_request():199] send_request: check_version
2021-10-02 12:42:36,438 DEBUG   SenderThread:36220 [sender.py:send():185] send: run
2021-10-02 12:42:36,720 ERROR   SenderThread:36220 [internal_api.py:execute():135] 403 response executing GraphQL.
2021-10-02 12:42:36,747 ERROR   SenderThread:36220 [internal_api.py:execute():136] {"errors":[{"message":"permission denied","path":["upsertBucket"],"extensions":{"code":"PERMISSION_ERROR"}}],"data":{"upsertBucket":null}}
2021-10-02 12:42:37,448 INFO    WriterThread:36220 [datastore.py:close():281] close: C:\Users\heinz\Documents\GitHub\Google_Brain-Ventilator_Pressure_Prediction\wandb\run-20211002_124233-c21n7t6e\run-c21n7t6e.wandb
2021-10-02 12:42:37,448 INFO    HandlerThread:36220 [handler.py:finish():683] shutting down handler
2021-10-02 12:42:37,449 ERROR   MainThread:36220 [internal.py:wandb_internal():157] Thread SenderThread:
Traceback (most recent call last):
  File "C:\Users\heinz\anaconda3\lib\site-packages\wandb\sdk\lib\retry.py", line 102, in __call__
    result = self._call_fn(*args, **kwargs)
  File "C:\Users\heinz\anaconda3\lib\site-packages\wandb\sdk\internal\internal_api.py", line 138, in execute
    six.reraise(*sys.exc_info())
  File "C:\Users\heinz\anaconda3\lib\site-packages\six.py", line 703, in reraise
    raise value
  File "C:\Users\heinz\anaconda3\lib\site-packages\wandb\sdk\internal\internal_api.py", line 132, in execute
    return self.client.execute(*args, **kwargs)
  File "C:\Users\heinz\anaconda3\lib\site-packages\wandb\vendor\gql-0.2.0\gql\client.py", line 52, in execute
    result = self._get_result(document, *args, **kwargs)
  File "C:\Users\heinz\anaconda3\lib\site-packages\wandb\vendor\gql-0.2.0\gql\client.py", line 60, in _get_result
    return self.transport.execute(document, *args, **kwargs)
  File "C:\Users\heinz\anaconda3\lib\site-packages\wandb\vendor\gql-0.2.0\gql\transport\requests.py", line 39, in execute
    request.raise_for_status()
  File "C:\Users\heinz\anaconda3\lib\site-packages\requests\models.py", line 909, in raise_for_status
    raise HTTPError(http_error_msg, response=self)
requests.exceptions.HTTPError: 403 Client Error: Forbidden for url: https://api.wandb.ai/graphql

During handling of the above exception, another exception occurred:

Traceback (most recent call last):
  File "C:\Users\heinz\anaconda3\lib\site-packages\wandb\apis\normalize.py", line 24, in wrapper
    return func(*args, **kwargs)
  File "C:\Users\heinz\anaconda3\lib\site-packages\wandb\sdk\internal\internal_api.py", line 1133, in upsert_run
    response = self.gql(mutation, variable_values=variable_values, **kwargs)
  File "C:\Users\heinz\anaconda3\lib\site-packages\wandb\sdk\lib\retry.py", line 118, in __call__
    if not check_retry_fn(e):
  File "C:\Users\heinz\anaconda3\lib\site-packages\wandb\util.py", line 815, in no_retry_auth
    raise CommError("Permission denied, ask the project owner to grant you access")
wandb.errors.CommError: Permission denied, ask the project owner to grant you access

During handling of the above exception, another exception occurred:

Traceback (most recent call last):
  File "C:\Users\heinz\anaconda3\lib\site-packages\wandb\sdk\internal\internal_util.py", line 52, in run
    self._run()
  File "C:\Users\heinz\anaconda3\lib\site-packages\wandb\sdk\internal\internal_util.py", line 102, in _run
    self._process(record)
  File "C:\Users\heinz\anaconda3\lib\site-packages\wandb\sdk\internal\internal.py", line 290, in _process
    self._sm.send(record)
  File "C:\Users\heinz\anaconda3\lib\site-packages\wandb\sdk\internal\sender.py", line 187, in send
    send_handler(record)
  File "C:\Users\heinz\anaconda3\lib\site-packages\wandb\sdk\internal\sender.py", line 629, in send_run
    self._init_run(run, config_value_dict)
  File "C:\Users\heinz\anaconda3\lib\site-packages\wandb\sdk\internal\sender.py", line 651, in _init_run
    server_run, inserted = self._api.upsert_run(
  File "C:\Users\heinz\anaconda3\lib\site-packages\wandb\apis\normalize.py", line 62, in wrapper
    six.reraise(CommError, CommError(message, err), sys.exc_info()[2])
  File "C:\Users\heinz\anaconda3\lib\site-packages\six.py", line 702, in reraise
    raise value.with_traceback(tb)
  File "C:\Users\heinz\anaconda3\lib\site-packages\wandb\apis\normalize.py", line 24, in wrapper
    return func(*args, **kwargs)
  File "C:\Users\heinz\anaconda3\lib\site-packages\wandb\sdk\internal\internal_api.py", line 1133, in upsert_run
    response = self.gql(mutation, variable_values=variable_values, **kwargs)
  File "C:\Users\heinz\anaconda3\lib\site-packages\wandb\sdk\lib\retry.py", line 118, in __call__
    if not check_retry_fn(e):
  File "C:\Users\heinz\anaconda3\lib\site-packages\wandb\util.py", line 815, in no_retry_auth
    raise CommError("Permission denied, ask the project owner to grant you access")
wandb.errors.CommError: Permission denied, ask the project owner to grant you access
2021-10-02 12:42:39,492 INFO    MainThread:36220 [internal.py:handle_exit():76] Internal process exited
